Workbook

Sheet دليل المستويات
A4: الدرجة | B4: المستوى | C4: المعنى المبسط | D4: منطق التدرج
A5: 1 | B5: ناشئ | C5: لا تطبق مؤسستنا الممارسة أو تطبقها بصورة محدودة جدًا. | D5: لا توجد ممارسة واضحة
A6: 2 | B6: أولي | C6: بدأت مؤسستنا بالممارسة بصورة بسيطة ومحدودة وغير منتظمة. | D6: بدأ التطبيق بصورة أولية
A7: 3 | B7: أساسي | C7: تطبق مؤسستنا ممارسة أساسية وواضحة، لكنها ليست منتظمة أو موثقة بالكامل. | D7: توجد ممارسة فعلية
A8: 4 | B8: منظم | C8: تطبق مؤسستنا إجراءات واضحة وموثقة بانتظام وتتابع تنفيذها. | D8: الممارسة منظمة ومتابعة
A9: 5 | B9: ديناميكي | C9: تحلل مؤسستنا النتائج وتراجع الممارسة وتطورها باستمرار وتستخدمها في التخطيط واتخاذ القرار. | D9: تحسين مستمر قائم على النتائج
A11: ملاحظة
A12: تم إعداد المستوى «أولي» كمرحلة تطور حقيقية بين «ناشئ» و«أساسي»، وليس كتقسيم لغوي فقط.

Sheet الترويج والخبرة في تعلم الكبار
A4: الترويج والخبرة في تعلم الكبار | B4: المؤشر / السؤال المبسط | C4: 1 - ناشئ | D4: 2 - أولي | E4: 3 - أساسي | F4: 4 - منظم | G4: 5 - ديناميكي | H4: الدرجة | I4: العلامة من 100
A5: تحسين الصورة العامة لتعلم وتعليم الكبار | B5: إلى أي مدى تعمل مؤسستك على تحسين الصورة العامة لتعلم وتعليم الكبار من خلال التواصل والإعلام والتوعية؟ | C5: لا تطبق مؤسستنا ممارسات واضحة في مجال تحسين الصورة العامة لتعلم وتعليم الكبار، وتتعامل معه عند الحاجة فقط. | D5: بدأت مؤسستنا باتخاذ خطوات بسيطة في مجال تحسين الصورة العامة لتعلم وتعليم الكبار، لكنها ما تزال محدودة وغير منتظمة. | E5: تطبق مؤسستنا ممارسات أساسية وواضحة في مجال تحسين الصورة العامة لتعلم وتعليم الكبار، لكنها لا تنفذها أو توثقها بشكل منتظم بالكامل. | F5: تطبق مؤسستنا إجراءات واضحة وموثقة في مجال تحسين الصورة العامة لتعلم وتعليم الكبار، وتنفذها بانتظام وتتابع نتائجها. | G5: تراجع مؤسستنا ممارسات تحسين الصورة العامة لتعلم وتعليم الكبار باستمرار، وتحلل النتائج والتغذية الراجعة وتستخدمها للتطوير واتخاذ القرارات. | H5: 1
A6: المشاركة في المعرفة والنقاشات | B6: إلى أي مدى تشارك مؤسستك في المعرفة والنقاشات المتعلقة بتعلم وتعليم الكبار محليًا ووطنيًا وإقليميًا ودوليًا؟ | C6: لا تطبق مؤسستنا ممارسات واضحة في مجال المشاركة في المعرفة والنقاشات، وتتعامل معه عند الحاجة فقط. | D6: بدأت مؤسستنا باتخاذ خطوات بسيطة في مجال المشاركة في المعرفة والنقاشات، لكنها ما تزال محدودة وغير منتظمة. | E6: تطبق مؤسستنا ممارسات أساسية وواضحة في مجال المشاركة في المعرفة والنقاشات، لكنها لا تنفذها أو توثقها بشكل منتظم بالكامل. | F6: تطبق مؤسستنا إجراءات واضحة وموثقة في مجال المشاركة في المعرفة والنقاشات، وتنفذها بانتظام وتتابع نتائجها. | G6: تراجع مؤسستنا ممارسات المشاركة في المعرفة والنقاشات باستمرار، وتحلل النتائج والتغذية الراجعة وتستخدمها للتطوير واتخاذ القرارات. | H6: 1
A7: المناصرة لتعلم وتعليم الكبار | B7: إلى أي مدى تناصر مؤسستك تعلم وتعليم الكبار لرفع الوعي والتأثير في السياسات وحشد الدعم والتمويل؟ | C7: لا تطبق مؤسستنا ممارسات واضحة في مجال المناصرة لتعلم وتعليم الكبار، وتتعامل معه عند الحاجة فقط. | D7: بدأت مؤسستنا باتخاذ خطوات بسيطة في مجال المناصرة لتعلم وتعليم الكبار، لكنها ما تزال محدودة وغير منتظمة. | E7: تطبق مؤسستنا ممارسات أساسية وواضحة في مجال المناصرة لتعلم وتعليم الكبار، لكنها لا تنفذها أو توثقها بشكل منتظم بالكامل. | F7: تطبق مؤسستنا إجراءات واضحة وموثقة في مجال المناصرة لتعلم وتعليم الكبار، وتنفذها بانتظام وتتابع نتائجها. | G7: تراجع مؤسستنا ممارسات المناصرة لتعلم وتعليم الكبار باستمرار، وتحلل النتائج والتغذية الراجعة وتستخدمها للتطوير واتخاذ القرارات. | H7: 1
A8: استخدام منهجيات تعلم الكبار | B8: إلى أي مدى تفهم مؤسستك منهجيات تعلم وتعليم الكبار وتستخدمها في برامجها التعليمية؟ | C8: لا تطبق مؤسستنا ممارسات واضحة في مجال استخدام منهجيات تعلم الكبار، وتتعامل معه عند الحاجة فقط. | D8: بدأت مؤسستنا باتخاذ خطوات بسيطة في مجال استخدام منهجيات تعلم الكبار، لكنها ما تزال محدودة وغير منتظمة. | E8: تطبق مؤسستنا ممارسات أساسية وواضحة في مجال استخدام منهجيات تعلم الكبار، لكنها لا تنفذها أو توثقها بشكل منتظم بالكامل. | F8: تطبق مؤسستنا إجراءات واضحة وموثقة في مجال استخدام منهجيات تعلم الكبار، وتنفذها بانتظام وتتابع نتائجها. | G8: تراجع مؤسستنا ممارسات استخدام منهجيات تعلم الكبار باستمرار، وتحلل النتائج والتغذية الراجعة وتستخدمها للتطوير واتخاذ القرارات. | H8: 1
A9: التشبيك والتعاون | B9: إلى أي مدى تتعاون مؤسستك مع مقدمي تعلم الكبار وأصحاب المصلحة والشبكات على المستويات المختلفة؟ | C9: لا تطبق مؤسستنا ممارسات واضحة في مجال التشبيك والتعاون، وتتعامل معه عند الحاجة فقط. | D9: بدأت مؤسستنا باتخاذ خطوات بسيطة في مجال التشبيك والتعاون، لكنها ما تزال محدودة وغير منتظمة. | E9: تطبق مؤسستنا ممارسات أساسية وواضحة في مجال التشبيك والتعاون، لكنها لا تنفذها أو توثقها بشكل منتظم بالكامل. | F9: تطبق مؤسستنا إجراءات واضحة وموثقة في مجال التشبيك والتعاون، وتنفذها بانتظام وتتابع نتائجها. | G9: تراجع مؤسستنا ممارسات التشبيك والتعاون باستمرار، وتحلل النتائج والتغذية الراجعة وتستخدمها للتطوير واتخاذ القرارات. | H9: 1
A10: تدريب الفريق على أساليب تعلم الكبار | B10: إلى أي مدى تدرب مؤسستك العاملين والمدربين على أساليب تعلم الكبار وتستخدم هذه الأساليب في تصميم وتنفيذ التدريب؟ | C10: لا تطبق مؤسستنا ممارسات واضحة في مجال تدريب الفريق على أساليب تعلم الكبار، وتتعامل معه عند الحاجة فقط. | D10: بدأت مؤسستنا باتخاذ خطوات بسيطة في مجال تدريب الفريق على أساليب تعلم الكبار، لكنها ما تزال محدودة وغير منتظمة. | E10: تطبق مؤسستنا ممارسات أساسية وواضحة في مجال تدريب الفريق على أساليب تعلم الكبار، لكنها لا تنفذها أو توثقها بشكل منتظم بالكامل. | F10: تطبق مؤسستنا إجراءات واضحة وموثقة في مجال تدريب الفريق على أساليب تعلم الكبار، وتنفذها بانتظام وتتابع نتائجها. | G10: تراجع مؤسستنا ممارسات تدريب الفريق على أساليب تعلم الكبار باستمرار، وتحلل النتائج والتغذية الراجعة وتستخدمها للتطوير واتخاذ القرارات. | H10: 1
G11: متوسط المجال | H11: =IFERROR(AVERAGE(H5:H10),"") -> 1 | I11: =H11*20 -> 20
A13: مصطلحات مساعدة | B13: شرح مبسط | D13: المصطلح | E13: التعريف
A14: تحسين الصورة العامة لتعلم وتعليم الكبار | B14: التواصل الاستراتيجي، الإعلام، التوعية، الصورة العامة | D14: الصورة العامة لتعلم وتعليم الكبار | E14: الطريقة التي يرى بها المجتمع أهمية تعلم وتعليم الكبار وفائدته.
A15: المشاركة في المعرفة والنقاشات | B15: تعلم وتعليم الكبار، تبادل المعرفة، الشبكات المهنية | D15: المناصرة | E15: العمل على رفع الوعي وكسب الدعم والتأثير في القرارات والسياسات لصالح تعلم وتعليم الكبار.
A16: المناصرة لتعلم وتعليم الكبار | B16: المناصرة، السياسات العامة، حشد الدعم | D16: الأندراغوجيا | E16: أسلوب تعليم الكبار الذي يعتمد على خبراتهم ومشاركتهم واحتياجاتهم الواقعية.
A17: استخدام منهجيات تعلم الكبار | B17: منهجيات تعلم الكبار، الأندراغوجيا، التعلم التشاركي | D17: أصحاب المصلحة | E17: الأشخاص أو الجهات التي تتأثر بعمل المؤسسة أو يمكن أن تؤثر فيه، مثل المتعلمين والشركاء والمانحين.
A18: التشبيك والتعاون | B18: التشبيك، الشراكات، أصحاب المصلحة
A19: تدريب الفريق على أساليب تعلم الكبار | B19: تطوير المدربين، الأندراغوجيا، التعليم الشعبي
D21: H5+H10

Sheet برامج تعلم وتعليم الكبار
A5: برامج تعلم وتعليم الكبار | B5: المؤشر / السؤال المبسط | C5: 1 - ناشئ | D5: 2 - أولي | E5: 3 - أساسي | F5: 4 - منظم | G5: 5 - ديناميكي | H5: الدرجة | I5: العلامة من 100
A6: تنوع وتنظيم البرامج التعليمية | B6: إلى أي مدى تقدم مؤسستك برامج تعليمية متنوعة ومنظمة تلبي احتياجات المتعلمين؟ | C6: لا تطبق مؤسستنا ممارسات واضحة في مجال تنوع وتنظيم البرامج التعليمية، وتتعامل معه عند الحاجة فقط. | D6: بدأت مؤسستنا باتخاذ خطوات بسيطة في مجال تنوع وتنظيم البرامج التعليمية، لكنها ما تزال محدودة وغير منتظمة. | E6: تطبق مؤسستنا ممارسات أساسية وواضحة في مجال تنوع وتنظيم البرامج التعليمية، لكنها لا تنفذها أو توثقها بشكل منتظم بالكامل. | F6: تطبق مؤسستنا إجراءات واضحة وموثقة في مجال تنوع وتنظيم البرامج التعليمية، وتنفذها بانتظام وتتابع نتائجها. | G6: تراجع مؤسستنا ممارسات تنوع وتنظيم البرامج التعليمية باستمرار، وتحلل النتائج والتغذية الراجعة وتستخدمها للتطوير واتخاذ القرارات. | H6: 1
A7: جودة المناهج وتقييمها | B7: إلى أي مدى تحافظ مؤسستك على جودة المناهج وتقيّمها وتطورها؟ | C7: لا تطبق مؤسستنا ممارسات واضحة في مجال جودة المناهج وتقييمها، وتتعامل معه عند الحاجة فقط. | D7: بدأت مؤسستنا باتخاذ خطوات بسيطة في مجال جودة المناهج وتقييمها، لكنها ما تزال محدودة وغير منتظمة. | E7: تطبق مؤسستنا ممارسات أساسية وواضحة في مجال جودة المناهج وتقييمها، لكنها لا تنفذها أو توثقها بشكل منتظم بالكامل. | F7: تطبق مؤسستنا إجراءات واضحة وموثقة في مجال جودة المناهج وتقييمها، وتنفذها بانتظام وتتابع نتائجها. | G7: تراجع مؤسستنا ممارسات جودة المناهج وتقييمها باستمرار، وتحلل النتائج والتغذية الراجعة وتستخدمها للتطوير واتخاذ القرارات. | H7: 1
A8: تنوع أشكال تقديم الدورات | B8: إلى أي مدى تنوع مؤسستك طرق تقديم الدورات مثل الوجاهي والرقمي والمدمج؟ | C8: لا تطبق مؤسستنا ممارسات واضحة في مجال تنوع أشكال تقديم الدورات، وتتعامل معه عند الحاجة فقط. | D8: بدأت مؤسستنا باتخاذ خطوات بسيطة في مجال تنوع أشكال تقديم الدورات، لكنها ما تزال محدودة وغير منتظمة. | E8: تطبق مؤسستنا ممارسات أساسية وواضحة في مجال تنوع أشكال تقديم الدورات، لكنها لا تنفذها أو توثقها بشكل منتظم بالكامل. | F8: تطبق مؤسستنا إجراءات واضحة وموثقة في مجال تنوع أشكال تقديم الدورات، وتنفذها بانتظام وتتابع نتائجها. | G8: تراجع مؤسستنا ممارسات تنوع أشكال تقديم الدورات باستمرار، وتحلل النتائج والتغذية الراجعة وتستخدمها للتطوير واتخاذ القرارات. | H8: 1
A9: إتاحة البرامج للمشاركين | B9: إلى أي مدى تجعل مؤسستك برامجها سهلة الوصول والمشاركة لمختلف الفئات؟ | C9: لا تطبق مؤسستنا ممارسات واضحة في مجال إتاحة البرامج للمشاركين، وتتعامل معه عند الحاجة فقط. | D9: بدأت مؤسستنا باتخاذ خطوات بسيطة في مجال إتاحة البرامج للمشاركين، لكنها ما تزال محدودة وغير منتظمة. | E9: تطبق مؤسستنا ممارسات أساسية وواضحة في مجال إتاحة البرامج للمشاركين، لكنها لا تنفذها أو توثقها بشكل منتظم بالكامل. | F9: تطبق مؤسستنا إجراءات واضحة وموثقة في مجال إتاحة البرامج للمشاركين، وتنفذها بانتظام وتتابع نتائجها. | G9: تراجع مؤسستنا ممارسات إتاحة البرامج للمشاركين باستمرار، وتحلل النتائج والتغذية الراجعة وتستخدمها للتطوير واتخاذ القرارات. | H9: 1
A10: تغذية المشاركين الراجعة ورضاهم | B10: إلى أي مدى تجمع مؤسستك آراء المشاركين وتقيس رضاهم وتستخدم النتائج لتحسين البرامج؟ | C10: لا تطبق مؤسستنا ممارسات واضحة في مجال تغذية المشاركين الراجعة ورضاهم، وتتعامل معه عند الحاجة فقط. | D10: بدأت مؤسستنا باتخاذ خطوات بسيطة في مجال تغذية المشاركين الراجعة ورضاهم، لكنها ما تزال محدودة وغير منتظمة. | E10: تطبق مؤسستنا ممارسات أساسية وواضحة في مجال تغذية المشاركين الراجعة ورضاهم، لكنها لا تنفذها أو توثقها بشكل منتظم بالكامل. | F10: تطبق مؤسستنا إجراءات واضحة وموثقة في مجال تغذية المشاركين الراجعة ورضاهم، وتنفذها بانتظام وتتابع نتائجها. | G10: تراجع مؤسستنا ممارسات تغذية المشاركين الراجعة ورضاهم باستمرار، وتحلل النتائج والتغذية الراجعة وتستخدمها للتطوير واتخاذ القرارات. | H10: 1
A11: التوجيه والإرشاد المهني | B11: إلى أي مدى تقدم مؤسستك خدمات التوجيه والإرشاد المهني للمتعلمين بصورة منظمة؟ | C11: لا تطبق مؤسستنا ممارسات واضحة في مجال التوجيه والإرشاد المهني، وتتعامل معه عند الحاجة فقط. | D11: بدأت مؤسستنا باتخاذ خطوات بسيطة في مجال التوجيه والإرشاد المهني، لكنها ما تزال محدودة وغير منتظمة. | E11: تطبق مؤسستنا ممارسات أساسية وواضحة في مجال التوجيه والإرشاد المهني، لكنها لا تنفذها أو توثقها بشكل منتظم بالكامل. | F11: تطبق مؤسستنا إجراءات واضحة وموثقة في مجال التوجيه والإرشاد المهني، وتنفذها بانتظام وتتابع نتائجها. | G11: تراجع مؤسستنا ممارسات التوجيه والإرشاد المهني باستمرار، وتحلل النتائج والتغذية الراجعة وتستخدمها للتطوير واتخاذ القرارات. | H11: 1
A12: تنفيذ الدورات بانتظام | B12: إلى أي مدى تنفذ مؤسستك الدورات وفق الخطط والجداول والمعايير المحددة؟ | C12: لا تطبق مؤسستنا ممارسات واضحة في مجال تنفيذ الدورات بانتظام، وتتعامل معه عند الحاجة فقط. | D12: بدأت مؤسستنا باتخاذ خطوات بسيطة في مجال تنفيذ الدورات بانتظام، لكنها ما تزال محدودة وغير منتظمة. | E12: تطبق مؤسستنا ممارسات أساسية وواضحة في مجال تنفيذ الدورات بانتظام، لكنها لا تنفذها أو توثقها بشكل منتظم بالكامل. | F12: تطبق مؤسستنا إجراءات واضحة وموثقة في مجال تنفيذ الدورات بانتظام، وتنفذها بانتظام وتتابع نتائجها. | G12: تراجع مؤسستنا ممارسات تنفيذ الدورات بانتظام باستمرار، وتحلل النتائج والتغذية الراجعة وتستخدمها للتطوير واتخاذ القرارات. | H12: 1
A13: ضمان جودة البرامج | B13: إلى أي مدى تطبق مؤسستك إجراءات لضمان جودة برامج تعلم وتعليم الكبار ونتائجها؟ | C13: لا تطبق مؤسستنا ممارسات واضحة في مجال ضمان جودة البرامج، وتتعامل معه عند الحاجة فقط. | D13: بدأت مؤسستنا باتخاذ خطوات بسيطة في مجال ضمان جودة البرامج، لكنها ما تزال محدودة وغير منتظمة. | E13: تطبق مؤسستنا ممارسات أساسية وواضحة في مجال ضمان جودة البرامج، لكنها لا تنفذها أو توثقها بشكل منتظم بالكامل. | F13: تطبق مؤسستنا إجراءات واضحة وموثقة في مجال ضمان جودة البرامج، وتنفذها بانتظام وتتابع نتائجها. | G13: تراجع مؤسستنا ممارسات ضمان جودة البرامج باستمرار، وتحلل النتائج والتغذية الراجعة وتستخدمها للتطوير واتخاذ القرارات. | H13: 1
A14: شمول الفئات المهمشة والأكثر عرضة للتهميش | B14: إلى أي مدى تصمم مؤسستك برامج تعلم كبار شاملة تستجيب لاحتياجات النساء واللاجئين والأشخاص ذوي الإعاقة وذوي الدخل المحدود وغيرهم؟ | C14: لا تطبق مؤسستنا ممارسات واضحة في مجال شمول الفئات المهمشة والأكثر عرضة للتهميش، وتتعامل معه عند الحاجة فقط. | D14: بدأت مؤسستنا باتخاذ خطوات بسيطة في مجال شمول الفئات المهمشة والأكثر عرضة للتهميش، لكنها ما تزال محدودة وغير منتظمة. | E14: تطبق مؤسستنا ممارسات أساسية وواضحة في مجال شمول الفئات المهمشة والأكثر عرضة للتهميش، لكنها لا تنفذها أو توثقها بشكل منتظم بالكامل. | F14: تطبق مؤسستنا إجراءات واضحة وموثقة في مجال شمول الفئات المهمشة والأكثر عرضة للتهميش، وتنفذها بانتظام وتتابع نتائجها. | G14: تراجع مؤسستنا ممارسات شمول الفئات المهمشة والأكثر عرضة للتهميش باستمرار، وتحلل النتائج والتغذية الراجعة وتستخدمها للتطوير واتخاذ القرارات. | H14: 1
G15: متوسط المجال | H15: =AVERAGE(H6:H14) -> 1 | I15: =H15*20 -> 20
A17: مصطلحات مساعدة | B17: شرح مبسط | D17: المصطلح | E17: التعريف
A18: تنوع وتنظيم البرامج التعليمية | B18: البرامج التعليمية، التنوع، هيكلة البرامج | D18: التعلم الرقمي | E18: التعلم باستخدام الإنترنت أو المنصات والأدوات الإلكترونية.
A19: جودة المناهج وتقييمها | B19: المناهج، تقييم الجودة، مراجعة المحتوى | D19: إتاحة البرامج | E19: جعل البرامج سهلة الوصول والمشاركة لمختلف الفئات، مع تقليل العوائق أمامهم.
A20: تنوع أشكال تقديم الدورات | B20: وجاهي، رقمي، مدمج | D20: التوجيه والإرشاد المهني | E20: مساعدة المتعلم على معرفة خياراته التعليمية والمهنية واختيار المسار المناسب له.
A21: إتاحة البرامج للمشاركين | B21: سهولة الوصول، العوائق، الترتيبات التيسيرية | D21: ضمان جودة البرامج | E21: التأكد من أن البرنامج يحقق المعايير المطلوبة ويقدم نتائج تعلم جيدة.
A22: تغذية المشاركين الراجعة ورضاهم | B22: التغذية الراجعة، رضا المشاركين، التحسين | D22: الفئات المهمشة | E22: فئات تواجه عوائق أو فرصًا أقل في الوصول إلى الخدمات والبرامج.
A23: التوجيه والإرشاد المهني | B23: التوجيه، الإرشاد المهني، المسار التعليمي
A24: تنفيذ الدورات بانتظام | B24: خطة الدورة، الجدول الزمني، انتظام التنفيذ
A25: ضمان جودة البرامج | B25: ضمان الجودة، المعايير، نتائج التعلم
A26: شمول الفئات المهمشة والأكثر عرضة للتهميش | B26: الشمول، الفئات المهمشة، إمكانية الوصول

Sheet البحث المجتمعي والتواصل
A5: البحث المجتمعي والتواصل | B5: المؤشر / السؤال المبسط | C5: 1 - ناشئ | D5: 2 - أولي | E5: 3 - أساسي | F5: 4 - منظم | G5: 5 - ديناميكي | H5: الدرجة | I5: العلامة من 100
A6: تحديد احتياجات الفئات المستهدفة | B6: إلى أي مدى تحدد مؤسستك احتياجات وتفضيلات الفئات المستهدفة من خلال البحث والمشاركة المجتمعية؟ | C6: لا تطبق مؤسستنا ممارسات واضحة في مجال تحديد احتياجات الفئات المستهدفة، وتتعامل معه عند الحاجة فقط. | D6: بدأت مؤسستنا باتخاذ خطوات بسيطة في مجال تحديد احتياجات الفئات المستهدفة، لكنها ما تزال محدودة وغير منتظمة. | E6: تطبق مؤسستنا ممارسات أساسية وواضحة في مجال تحديد احتياجات الفئات المستهدفة، لكنها لا تنفذها أو توثقها بشكل منتظم بالكامل. | F6: تطبق مؤسستنا إجراءات واضحة وموثقة في مجال تحديد احتياجات الفئات المستهدفة، وتنفذها بانتظام وتتابع نتائجها. | G6: تراجع مؤسستنا ممارسات تحديد احتياجات الفئات المستهدفة باستمرار، وتحلل النتائج والتغذية الراجعة وتستخدمها للتطوير واتخاذ القرارات. | H6: 1
A7: حملات الوصول والاستقطاب | B7: إلى أي مدى تنفذ مؤسستك حملات موجهة لزيادة الوعي ببرامجها وتشجيع التسجيل فيها؟ | C7: لا تطبق مؤسستنا ممارسات واضحة في مجال حملات الوصول والاستقطاب، وتتعامل معه عند الحاجة فقط. | D7: بدأت مؤسستنا باتخاذ خطوات بسيطة في مجال حملات الوصول والاستقطاب، لكنها ما تزال محدودة وغير منتظمة. | E7: تطبق مؤسستنا ممارسات أساسية وواضحة في مجال حملات الوصول والاستقطاب، لكنها لا تنفذها أو توثقها بشكل منتظم بالكامل. | F7: تطبق مؤسستنا إجراءات واضحة وموثقة في مجال حملات الوصول والاستقطاب، وتنفذها بانتظام وتتابع نتائجها. | G7: تراجع مؤسستنا ممارسات حملات الوصول والاستقطاب باستمرار، وتحلل النتائج والتغذية الراجعة وتستخدمها للتطوير واتخاذ القرارات. | H7: 1
A8: دعم المتعلمين واستمرارهم | B8: إلى أي مدى تدعم مؤسستك المتعلمين خلال رحلتهم التعليمية لمساعدتهم على النجاح وإكمال البرامج؟ | C8: لا تطبق مؤسستنا ممارسات واضحة في مجال دعم المتعلمين واستمرارهم، وتتعامل معه عند الحاجة فقط. | D8: بدأت مؤسستنا باتخاذ خطوات بسيطة في مجال دعم المتعلمين واستمرارهم، لكنها ما تزال محدودة وغير منتظمة. | E8: تطبق مؤسستنا ممارسات أساسية وواضحة في مجال دعم المتعلمين واستمرارهم، لكنها لا تنفذها أو توثقها بشكل منتظم بالكامل. | F8: تطبق مؤسستنا إجراءات واضحة وموثقة في مجال دعم المتعلمين واستمرارهم، وتنفذها بانتظام وتتابع نتائجها. | G8: تراجع مؤسستنا ممارسات دعم المتعلمين واستمرارهم باستمرار، وتحلل النتائج والتغذية الراجعة وتستخدمها للتطوير واتخاذ القرارات. | H8: 1
A9: قياس نتائج المشاركين | B9: إلى أي مدى تتابع مؤسستك نتائج المشاركين وتقيسها لإظهار فعالية البرامج التعليمية؟ | C9: لا تطبق مؤسستنا ممارسات واضحة في مجال قياس نتائج المشاركين، وتتعامل معه عند الحاجة فقط. | D9: بدأت مؤسستنا باتخاذ خطوات بسيطة في مجال قياس نتائج المشاركين، لكنها ما تزال محدودة وغير منتظمة. | E9: تطبق مؤسستنا ممارسات أساسية وواضحة في مجال قياس نتائج المشاركين، لكنها لا تنفذها أو توثقها بشكل منتظم بالكامل. | F9: تطبق مؤسستنا إجراءات واضحة وموثقة في مجال قياس نتائج المشاركين، وتنفذها بانتظام وتتابع نتائجها. | G9: تراجع مؤسستنا ممارسات قياس نتائج المشاركين باستمرار، وتحلل النتائج والتغذية الراجعة وتستخدمها للتطوير واتخاذ القرارات. | H9: 1
A10: مشاركة الخريجين في تنمية المجتمع | B10: إلى أي مدى تشجع مؤسستك الخريجين وتدعمهم للمشاركة في أنشطة تخدم تنمية المجتمع؟ | C10: لا تطبق مؤسستنا ممارسات واضحة في مجال مشاركة الخريجين في تنمية المجتمع، وتتعامل معه عند الحاجة فقط. | D10: بدأت مؤسستنا باتخاذ خطوات بسيطة في مجال مشاركة الخريجين في تنمية المجتمع، لكنها ما تزال محدودة وغير منتظمة. | E10: تطبق مؤسستنا ممارسات أساسية وواضحة في مجال مشاركة الخريجين في تنمية المجتمع، لكنها لا تنفذها أو توثقها بشكل منتظم بالكامل. | F10: تطبق مؤسستنا إجراءات واضحة وموثقة في مجال مشاركة الخريجين في تنمية المجتمع، وتنفذها بانتظام وتتابع نتائجها. | G10: تراجع مؤسستنا ممارسات مشاركة الخريجين في تنمية المجتمع باستمرار، وتحلل النتائج والتغذية الراجعة وتستخدمها للتطوير واتخاذ القرارات. | H10: 1
A11: الترويج للبرامج التعليمية | B11: إلى أي مدى تروج مؤسستك لبرامجها التعليمية وتوضح قيمتها لجذب المشاركين؟ | C11: لا تطبق مؤسستنا ممارسات واضحة في مجال الترويج للبرامج التعليمية، وتتعامل معه عند الحاجة فقط. | D11: بدأت مؤسستنا باتخاذ خطوات بسيطة في مجال الترويج للبرامج التعليمية، لكنها ما تزال محدودة وغير منتظمة. | E11: تطبق مؤسستنا ممارسات أساسية وواضحة في مجال الترويج للبرامج التعليمية، لكنها لا تنفذها أو توثقها بشكل منتظم بالكامل. | F11: تطبق مؤسستنا إجراءات واضحة وموثقة في مجال الترويج للبرامج التعليمية، وتنفذها بانتظام وتتابع نتائجها. | G11: تراجع مؤسستنا ممارسات الترويج للبرامج التعليمية باستمرار، وتحلل النتائج والتغذية الراجعة وتستخدمها للتطوير واتخاذ القرارات. | H11: 1
A12: إشراك المجتمع في تطوير البرامج | B12: إلى أي مدى تجمع مؤسستك آراء المجتمع وتستخدمها في تطوير البرامج؟ | C12: لا تطبق مؤسستنا ممارسات واضحة في مجال إشراك المجتمع في تطوير البرامج، وتتعامل معه عند الحاجة فقط. | D12: بدأت مؤسستنا باتخاذ خطوات بسيطة في مجال إشراك المجتمع في تطوير البرامج، لكنها ما تزال محدودة وغير منتظمة. | E12: تطبق مؤسستنا ممارسات أساسية وواضحة في مجال إشراك المجتمع في تطوير البرامج، لكنها لا تنفذها أو توثقها بشكل منتظم بالكامل. | F12: تطبق مؤسستنا إجراءات واضحة وموثقة في مجال إشراك المجتمع في تطوير البرامج، وتنفذها بانتظام وتتابع نتائجها. | G12: تراجع مؤسستنا ممارسات إشراك المجتمع في تطوير البرامج باستمرار، وتحلل النتائج والتغذية الراجعة وتستخدمها للتطوير واتخاذ القرارات. | H12: 1
G13: متوسط المجال | H13: =(H6+H7+H8+H9+H10+H11+H12)/7 -> 1 | I13: =H13*20 -> 20
A15: مصطلحات مساعدة | B15: شرح مبسط | D15: المصطلح | E15: التعريف
A16: تحديد احتياجات الفئات المستهدفة | B16: البحث المجتمعي، الاحتياجات، الفئات المستهدفة | D16: البحث المجتمعي | E16: جمع معلومات من المجتمع لفهم احتياجات الناس ومشكلاتهم وتفضيلاتهم.
A17: حملات الوصول والاستقطاب | B17: الوصول، الاستقطاب، التسجيل | D17: حملات الوصول | E17: أنشطة تهدف إلى الوصول إلى الفئات المستهدفة وتعريفها بالبرامج.
A18: دعم المتعلمين واستمرارهم | B18: دعم المتعلمين، الاستمرار، إكمال البرنامج | D18: الاستقطاب | E18: تشجيع الأشخاص المناسبين على الاهتمام بالبرنامج والتسجيل فيه.
A19: قياس نتائج المشاركين | B19: النتائج، المتابعة، فعالية البرامج | D19: فعالية البرامج | E19: مدى نجاح البرنامج في تحقيق أهدافه ونتائجه المطلوبة.
A20: مشاركة الخريجين في تنمية المجتمع | B20: الخريجون، المشاركة المجتمعية، تنمية المجتمع | D20: المشاركة المجتمعية | E20: إشراك أفراد المجتمع في إبداء الرأي أو تنفيذ الأنشطة أو تطوير البرامج.
A21: الترويج للبرامج التعليمية | B21: الترويج، القيمة المضافة، استقطاب المشاركين
A22: إشراك المجتمع في تطوير البرامج | B22: مشاركة المجتمع، التغذية الراجعة، تطوير البرامج

Sheet التواصل والمناصرة
A5: التواصل والمناصرة | B5: المؤشر / السؤال المبسط | C5: 1 - ناشئ | D5: 2 - أولي | E5: 3 - أساسي | F5: 4 - منظم | G5: 5 - ديناميكي | H5: الدرجة | I5: العلامة من 100
A6: خطة التواصل | B6: إلى أي مدى تضع مؤسستك خطة واضحة للتواصل مع الجمهور وأصحاب المصلحة وتستخدمها؟ | C6: لا تطبق مؤسستنا ممارسات واضحة في مجال خطة التواصل، وتتعامل معه عند الحاجة فقط. | D6: بدأت مؤسستنا باتخاذ خطوات بسيطة في مجال خطة التواصل، لكنها ما تزال محدودة وغير منتظمة. | E6: تطبق مؤسستنا ممارسات أساسية وواضحة في مجال خطة التواصل، لكنها لا تنفذها أو توثقها بشكل منتظم بالكامل. | F6: تطبق مؤسستنا إجراءات واضحة وموثقة في مجال خطة التواصل، وتنفذها بانتظام وتتابع نتائجها. | G6: تراجع مؤسستنا ممارسات خطة التواصل باستمرار، وتحلل النتائج والتغذية الراجعة وتستخدمها للتطوير واتخاذ القرارات. | H6: 1
A7: التواصل الداخلي | B7: إلى أي مدى تُبقي مؤسستك العاملين والمدربين على اطلاع وتشركهم من خلال تواصل داخلي فعال؟ | C7: لا تطبق مؤسستنا ممارسات واضحة في مجال التواصل الداخلي، وتتعامل معه عند الحاجة فقط. | D7: بدأت مؤسستنا باتخاذ خطوات بسيطة في مجال التواصل الداخلي، لكنها ما تزال محدودة وغير منتظمة. | E7: تطبق مؤسستنا ممارسات أساسية وواضحة في مجال التواصل الداخلي، لكنها لا تنفذها أو توثقها بشكل منتظم بالكامل. | F7: تطبق مؤسستنا إجراءات واضحة وموثقة في مجال التواصل الداخلي، وتنفذها بانتظام وتتابع نتائجها. | G7: تراجع مؤسستنا ممارسات التواصل الداخلي باستمرار، وتحلل النتائج والتغذية الراجعة وتستخدمها للتطوير واتخاذ القرارات. | H7: 1
A8: تحسين الصورة العامة لتعلم الكبار | B8: إلى أي مدى تعمل مؤسستك على تحسين نظرة الجمهور لتعلم وتعليم الكبار من خلال الحملات والتواصل مع الإعلام؟ | C8: لا تطبق مؤسستنا ممارسات واضحة في مجال تحسين الصورة العامة لتعلم الكبار، وتتعامل معه عند الحاجة فقط. | D8: بدأت مؤسستنا باتخاذ خطوات بسيطة في مجال تحسين الصورة العامة لتعلم الكبار، لكنها ما تزال محدودة وغير منتظمة. | E8: تطبق مؤسستنا ممارسات أساسية وواضحة في مجال تحسين الصورة العامة لتعلم الكبار، لكنها لا تنفذها أو توثقها بشكل منتظم بالكامل. | F8: تطبق مؤسستنا إجراءات واضحة وموثقة في مجال تحسين الصورة العامة لتعلم الكبار، وتنفذها بانتظام وتتابع نتائجها. | G8: تراجع مؤسستنا ممارسات تحسين الصورة العامة لتعلم الكبار باستمرار، وتحلل النتائج والتغذية الراجعة وتستخدمها للتطوير واتخاذ القرارات. | H8: 1
A9: استخدام الأدوات الرقمية | B9: إلى أي مدى تستخدم مؤسستك وسائل التواصل الاجتماعي والموقع الإلكتروني والأدوات الرقمية للوصول إلى الجمهور؟ | C9: لا تطبق مؤسستنا ممارسات واضحة في مجال استخدام الأدوات الرقمية، وتتعامل معه عند الحاجة فقط. | D9: بدأت مؤسستنا باتخاذ خطوات بسيطة في مجال استخدام الأدوات الرقمية، لكنها ما تزال محدودة وغير منتظمة. | E9: تطبق مؤسستنا ممارسات أساسية وواضحة في مجال استخدام الأدوات الرقمية، لكنها لا تنفذها أو توثقها بشكل منتظم بالكامل. | F9: تطبق مؤسستنا إجراءات واضحة وموثقة في مجال استخدام الأدوات الرقمية، وتنفذها بانتظام وتتابع نتائجها. | G9: تراجع مؤسستنا ممارسات استخدام الأدوات الرقمية باستمرار، وتحلل النتائج والتغذية الراجعة وتستخدمها للتطوير واتخاذ القرارات. | H9: 1
A10: استخدام التغذية الراجعة لتحسين التواصل | B10: إلى أي مدى تجمع مؤسستك التغذية الراجعة وتستخدمها لتحسين التواصل والمشاركة؟ | C10: لا تطبق مؤسستنا ممارسات واضحة في مجال استخدام التغذية الراجعة لتحسين التواصل، وتتعامل معه عند الحاجة فقط. | D10: بدأت مؤسستنا باتخاذ خطوات بسيطة في مجال استخدام التغذية الراجعة لتحسين التواصل، لكنها ما تزال محدودة وغير منتظمة. | E10: تطبق مؤسستنا ممارسات أساسية وواضحة في مجال استخدام التغذية الراجعة لتحسين التواصل، لكنها لا تنفذها أو توثقها بشكل منتظم بالكامل. | F10: تطبق مؤسستنا إجراءات واضحة وموثقة في مجال استخدام التغذية الراجعة لتحسين التواصل، وتنفذها بانتظام وتتابع نتائجها. | G10: تراجع مؤسستنا ممارسات استخدام التغذية الراجعة لتحسين التواصل باستمرار، وتحلل النتائج والتغذية الراجعة وتستخدمها للتطوير واتخاذ القرارات. | H10: 1
A11: الشفافية في التواصل | B11: إلى أي مدى تضمن مؤسستك أن يكون تواصلها واضحًا وصادقًا وشفافًا بما يعزز الثقة؟ | C11: لا تطبق مؤسستنا ممارسات واضحة في مجال الشفافية في التواصل، وتتعامل معه عند الحاجة فقط. | D11: بدأت مؤسستنا باتخاذ خطوات بسيطة في مجال الشفافية في التواصل، لكنها ما تزال محدودة وغير منتظمة. | E11: تطبق مؤسستنا ممارسات أساسية وواضحة في مجال الشفافية في التواصل، لكنها لا تنفذها أو توثقها بشكل منتظم بالكامل. | F11: تطبق مؤسستنا إجراءات واضحة وموثقة في مجال الشفافية في التواصل، وتنفذها بانتظام وتتابع نتائجها. | G11: تراجع مؤسستنا ممارسات الشفافية في التواصل باستمرار، وتحلل النتائج والتغذية الراجعة وتستخدمها للتطوير واتخاذ القرارات. | H11: 1
G12: متوسط المجال | H12: =(H6+H7+H8+H9+H10+H11)/6 -> 1 | I12: =H12*20 -> 20
A14: مصطلحات مساعدة | B14: شرح مبسط | D14: المصطلح | E14: التعريف
A15: خطة التواصل | B15: خطة التواصل، الجمهور المستهدف، الرسائل | D15: خطة التواصل | E15: خطة تحدد مع من نتواصل، وما الرسالة التي نريد إيصالها، وبأي وسيلة ومتى.
A16: التواصل الداخلي | B16: التواصل الداخلي، مشاركة المعلومات، الفريق | D16: التواصل الداخلي | E16: تبادل المعلومات والتعليمات بين الإدارة والعاملين والمدربين داخل المؤسسة.
A17: تحسين الصورة العامة لتعلم الكبار | B17: الحملات، الإعلام، الصورة العامة | D17: الأدوات الرقمية | E17: وسائل إلكترونية تساعد على التواصل والوصول إلى الجمهور، مثل الموقع ووسائل التواصل الاجتماعي.
A18: استخدام الأدوات الرقمية | B18: وسائل التواصل الاجتماعي، الموقع الإلكتروني، الوصول الرقمي | D18: الشفافية | E18: تقديم المعلومات بوضوح وصدق وعدم إخفاء المعلومات المهمة عن الجهات المعنية.
A19: استخدام التغذية الراجعة لتحسين التواصل | B19: التغذية الراجعة، المشاركة، تحسين التواصل | D19: الإفصاح | E19: مشاركة المعلومات أو البيانات التي ينبغي أن تكون معروفة لأصحاب العلاقة.
A20: الشفافية في التواصل | B20: الشفافية، الثقة، الإفصاح

Sheet الموارد البشرية
A5: الموارد البشرية | B5: المؤشر / السؤال المبسط | C5: 1 - ناشئ | D5: 2 - أولي | E5: 3 - أساسي | F5: 4 - منظم | G5: 5 - ديناميكي | H5: الدرجة | I5: العلامة من 100
A6: تحديد الأدوار والمسؤوليات | B6: إلى أي مدى تحدد مؤسستك أدوار العاملين ومسؤولياتهم وتوثقها؟ | C6: لا تطبق مؤسستنا ممارسات واضحة في مجال تحديد الأدوار والمسؤوليات، وتتعامل معه عند الحاجة فقط. | D6: بدأت مؤسستنا باتخاذ خطوات بسيطة في مجال تحديد الأدوار والمسؤوليات، لكنها ما تزال محدودة وغير منتظمة. | E6: تطبق مؤسستنا ممارسات أساسية وواضحة في مجال تحديد الأدوار والمسؤوليات، لكنها لا تنفذها أو توثقها بشكل منتظم بالكامل. | F6: تطبق مؤسستنا إجراءات واضحة وموثقة في مجال تحديد الأدوار والمسؤوليات، وتنفذها بانتظام وتتابع نتائجها. | G6: تراجع مؤسستنا ممارسات تحديد الأدوار والمسؤوليات باستمرار، وتحلل النتائج والتغذية الراجعة وتستخدمها للتطوير واتخاذ القرارات. | H6: 1
A7: التوظيف والاختيار | B7: إلى أي مدى تطبق مؤسستك إجراءات واضحة ومنظمة لاستقطاب العاملين واختيارهم وتوظيفهم؟ | C7: لا تطبق مؤسستنا ممارسات واضحة في مجال التوظيف والاختيار، وتتعامل معه عند الحاجة فقط. | D7: بدأت مؤسستنا باتخاذ خطوات بسيطة في مجال التوظيف والاختيار، لكنها ما تزال محدودة وغير منتظمة. | E7: تطبق مؤسستنا ممارسات أساسية وواضحة في مجال التوظيف والاختيار، لكنها لا تنفذها أو توثقها بشكل منتظم بالكامل. | F7: تطبق مؤسستنا إجراءات واضحة وموثقة في مجال التوظيف والاختيار، وتنفذها بانتظام وتتابع نتائجها. | G7: تراجع مؤسستنا ممارسات التوظيف والاختيار باستمرار، وتحلل النتائج والتغذية الراجعة وتستخدمها للتطوير واتخاذ القرارات. | H7: 1
A8: التطوير المهني | B8: إلى أي مدى توفر مؤسستك فرص التطوير المهني للعاملين والمدربين؟ | C8: لا تطبق مؤسستنا ممارسات واضحة في مجال التطوير المهني، وتتعامل معه عند الحاجة فقط. | D8: بدأت مؤسستنا باتخاذ خطوات بسيطة في مجال التطوير المهني، لكنها ما تزال محدودة وغير منتظمة. | E8: تطبق مؤسستنا ممارسات أساسية وواضحة في مجال التطوير المهني، لكنها لا تنفذها أو توثقها بشكل منتظم بالكامل. | F8: تطبق مؤسستنا إجراءات واضحة وموثقة في مجال التطوير المهني، وتنفذها بانتظام وتتابع نتائجها. | G8: تراجع مؤسستنا ممارسات التطوير المهني باستمرار، وتحلل النتائج والتغذية الراجعة وتستخدمها للتطوير واتخاذ القرارات. | H8: 1
A9: تقييم الأداء | B9: إلى أي مدى تقيّم مؤسستك أداء العاملين وتستخدم النتائج لتطويرهم؟ | C9: لا تطبق مؤسستنا ممارسات واضحة في مجال تقييم الأداء، وتتعامل معه عند الحاجة فقط. | D9: بدأت مؤسستنا باتخاذ خطوات بسيطة في مجال تقييم الأداء، لكنها ما تزال محدودة وغير منتظمة. | E9: تطبق مؤسستنا ممارسات أساسية وواضحة في مجال تقييم الأداء، لكنها لا تنفذها أو توثقها بشكل منتظم بالكامل. | F9: تطبق مؤسستنا إجراءات واضحة وموثقة في مجال تقييم الأداء، وتنفذها بانتظام وتتابع نتائجها. | G9: تراجع مؤسستنا ممارسات تقييم الأداء باستمرار، وتحلل النتائج والتغذية الراجعة وتستخدمها للتطوير واتخاذ القرارات. | H9: 1
A10: إشراك المتطوعين | B10: إلى أي مدى تستقطب مؤسستك المتطوعين وتنظم مشاركتهم وتدعم استمرارهم؟ | C10: لا تطبق مؤسستنا ممارسات واضحة في مجال إشراك المتطوعين، وتتعامل معه عند الحاجة فقط. | D10: بدأت مؤسستنا باتخاذ خطوات بسيطة في مجال إشراك المتطوعين، لكنها ما تزال محدودة وغير منتظمة. | E10: تطبق مؤسستنا ممارسات أساسية وواضحة في مجال إشراك المتطوعين، لكنها لا تنفذها أو توثقها بشكل منتظم بالكامل. | F10: تطبق مؤسستنا إجراءات واضحة وموثقة في مجال إشراك المتطوعين، وتنفذها بانتظام وتتابع نتائجها. | G10: تراجع مؤسستنا ممارسات إشراك المتطوعين باستمرار، وتحلل النتائج والتغذية الراجعة وتستخدمها للتطوير واتخاذ القرارات. | H10: 1
A11: الرضا الوظيفي والرفاه | B11: إلى أي مدى تهتم مؤسستك برضا العاملين ورفاههم وتستجيب لاحتياجاتهم؟ | C11: لا تطبق مؤسستنا ممارسات واضحة في مجال الرضا الوظيفي والرفاه، وتتعامل معه عند الحاجة فقط. | D11: بدأت مؤسستنا باتخاذ خطوات بسيطة في مجال الرضا الوظيفي والرفاه، لكنها ما تزال محدودة وغير منتظمة. | E11: تطبق مؤسستنا ممارسات أساسية وواضحة في مجال الرضا الوظيفي والرفاه، لكنها لا تنفذها أو توثقها بشكل منتظم بالكامل. | F11: تطبق مؤسستنا إجراءات واضحة وموثقة في مجال الرضا الوظيفي والرفاه، وتنفذها بانتظام وتتابع نتائجها. | G11: تراجع مؤسستنا ممارسات الرضا الوظيفي والرفاه باستمرار، وتحلل النتائج والتغذية الراجعة وتستخدمها للتطوير واتخاذ القرارات. | H11: 1
G12: متوسط المجال | H12: =(H6+H7+H8+H9+H10+H11)/6 -> 1 | I12: =H12*20 -> 20
A14: مصطلحات مساعدة | B14: شرح مبسط | D14: المصطلح | E14: التعريف
A15: تحديد الأدوار والمسؤوليات | B15: الوصف الوظيفي، الأدوار، المسؤوليات | D15: الموارد البشرية | E15: العاملون والمدربون والمتطوعون الذين يساهمون في عمل المؤسسة.
A16: التوظيف والاختيار | B16: التوظيف، الاختيار، إجراءات الاستقطاب | D16: الأدوار والمسؤوليات | E16: المهام التي يقوم بها كل شخص وما هو مطلوب منه داخل المؤسسة.
A17: التطوير المهني | B17: التطوير المهني، التدريب، بناء القدرات | D17: الوصف الوظيفي | E17: وثيقة توضّح مهام الوظيفة ومسؤولياتها ومؤهلات شاغلها.
A18: تقييم الأداء | B18: تقييم الأداء، التغذية الراجعة، التطوير | D18: التطوير المهني | E18: تدريب العاملين وتحسين مهاراتهم وخبراتهم المرتبطة بالعمل.
A19: إشراك المتطوعين | B19: المتطوعون، الاستقطاب، إدارة التطوع | D19: تقييم الأداء | E19: مراجعة أداء العامل ومعرفة نقاط القوة ومجالات التحسين لديه.
A20: الرضا الوظيفي والرفاه | B20: الرضا الوظيفي، الرفاه، بيئة العمل | D20: الرضا الوظيفي والرفاه | E20: شعور العاملين بالراحة والتقدير والرضا عن بيئة العمل وظروفه.

Sheet  التمويل وكتابة المشاريع
A5: جمع التمويل وكتابة المشاريع | B5: المؤشر / السؤال المبسط | C5: 1 - ناشئ | D5: 2 - أولي | E5: 3 - أساسي | F5: 4 - منظم | G5: 5 - ديناميكي | H5: الدرجة | I5: العلامة من 100
A6: تنويع مصادر التمويل | B6: إلى أي مدى تنوع مؤسستك مصادر التمويل ولا تعتمد على مصدر واحد؟ | C6: لا تطبق مؤسستنا ممارسات واضحة في مجال تنويع مصادر التمويل، وتتعامل معه عند الحاجة فقط. | D6: بدأت مؤسستنا باتخاذ خطوات بسيطة في مجال تنويع مصادر التمويل، لكنها ما تزال محدودة وغير منتظمة. | E6: تطبق مؤسستنا ممارسات أساسية وواضحة في مجال تنويع مصادر التمويل، لكنها لا تنفذها أو توثقها بشكل منتظم بالكامل. | F6: تطبق مؤسستنا إجراءات واضحة وموثقة في مجال تنويع مصادر التمويل، وتنفذها بانتظام وتتابع نتائجها. | G6: تراجع مؤسستنا ممارسات تنويع مصادر التمويل باستمرار، وتحلل النتائج والتغذية الراجعة وتستخدمها للتطوير واتخاذ القرارات. | H6: 1
A7: إدارة علاقات المانحين | B7: إلى أي مدى تدير مؤسستك علاقاتها مع المانحين والداعمين وتحافظ عليها؟ | C7: لا تطبق مؤسستنا ممارسات واضحة في مجال إدارة علاقات المانحين، وتتعامل معه عند الحاجة فقط. | D7: بدأت مؤسستنا باتخاذ خطوات بسيطة في مجال إدارة علاقات المانحين، لكنها ما تزال محدودة وغير منتظمة. | E7: تطبق مؤسستنا ممارسات أساسية وواضحة في مجال إدارة علاقات المانحين، لكنها لا تنفذها أو توثقها بشكل منتظم بالكامل. | F7: تطبق مؤسستنا إجراءات واضحة وموثقة في مجال إدارة علاقات المانحين، وتنفذها بانتظام وتتابع نتائجها. | G7: تراجع مؤسستنا ممارسات إدارة علاقات المانحين باستمرار، وتحلل النتائج والتغذية الراجعة وتستخدمها للتطوير واتخاذ القرارات. | H7: 1
A8: كتابة المنح والمقترحات | B8: إلى أي مدى تمتلك مؤسستك القدرة على إعداد وكتابة مقترحات المشاريع وطلبات المنح؟ | C8: لا تطبق مؤسستنا ممارسات واضحة في مجال كتابة المنح والمقترحات، وتتعامل معه عند الحاجة فقط. | D8: بدأت مؤسستنا باتخاذ خطوات بسيطة في مجال كتابة المنح والمقترحات، لكنها ما تزال محدودة وغير منتظمة. | E8: تطبق مؤسستنا ممارسات أساسية وواضحة في مجال كتابة المنح والمقترحات، لكنها لا تنفذها أو توثقها بشكل منتظم بالكامل. | F8: تطبق مؤسستنا إجراءات واضحة وموثقة في مجال كتابة المنح والمقترحات، وتنفذها بانتظام وتتابع نتائجها. | G8: تراجع مؤسستنا ممارسات كتابة المنح والمقترحات باستمرار، وتحلل النتائج والتغذية الراجعة وتستخدمها للتطوير واتخاذ القرارات. | H8: 1
A9: التخطيط المالي طويل المدى | B9: إلى أي مدى تربط مؤسستك جهود جمع التمويل بخططها المالية طويلة المدى؟ | C9: لا تطبق مؤسستنا ممارسات واضحة في مجال التخطيط المالي طويل المدى، وتتعامل معه عند الحاجة فقط. | D9: بدأت مؤسستنا باتخاذ خطوات بسيطة في مجال التخطيط المالي طويل المدى، لكنها ما تزال محدودة وغير منتظمة. | E9: تطبق مؤسستنا ممارسات أساسية وواضحة في مجال التخطيط المالي طويل المدى، لكنها لا تنفذها أو توثقها بشكل منتظم بالكامل. | F9: تطبق مؤسستنا إجراءات واضحة وموثقة في مجال التخطيط المالي طويل المدى، وتنفذها بانتظام وتتابع نتائجها. | G9: تراجع مؤسستنا ممارسات التخطيط المالي طويل المدى باستمرار، وتحلل النتائج والتغذية الراجعة وتستخدمها للتطوير واتخاذ القرارات. | H9: 1
A10: تطوير قدرات الفريق في جمع التمويل | B10: إلى أي مدى تطور مؤسستك مهارات العاملين في جمع التمويل وكتابة المقترحات؟ | C10: لا تطبق مؤسستنا ممارسات واضحة في مجال تطوير قدرات الفريق في جمع التمويل، وتتعامل معه عند الحاجة فقط. | D10: بدأت مؤسستنا باتخاذ خطوات بسيطة في مجال تطوير قدرات الفريق في جمع التمويل، لكنها ما تزال محدودة وغير منتظمة. | E10: تطبق مؤسستنا ممارسات أساسية وواضحة في مجال تطوير قدرات الفريق في جمع التمويل، لكنها لا تنفذها أو توثقها بشكل منتظم بالكامل. | F10: تطبق مؤسستنا إجراءات واضحة وموثقة في مجال تطوير قدرات الفريق في جمع التمويل، وتنفذها بانتظام وتتابع نتائجها. | G10: تراجع مؤسستنا ممارسات تطوير قدرات الفريق في جمع التمويل باستمرار، وتحلل النتائج والتغذية الراجعة وتستخدمها للتطوير واتخاذ القرارات. | H10: 1
G11: متوسط المجال | H11: =(H6+H7+H8+H9+H10)/5 -> 1 | I11: =H11*20 -> 20
A13: مصطلحات مساعدة | B13: شرح مبسط | D13: المصطلح | E13: التعريف
A14: تنويع مصادر التمويل | B14: مصادر التمويل، التنويع، الاستدامة المالية | D14: تنويع مصادر التمويل | E14: الحصول على التمويل من أكثر من مصدر وعدم الاعتماد على جهة واحدة فقط.
A15: إدارة علاقات المانحين | B15: المانحون، الداعمون، إدارة العلاقات | D15: الاستدامة المالية | E15: قدرة المؤسسة على الاستمرار في تنفيذ عملها وتغطية احتياجاتها المالية مع مرور الوقت.
A16: كتابة المنح والمقترحات | B16: كتابة المقترحات، المنح، فرص التمويل | D16: إدارة علاقات المانحين | E16: التواصل مع المانحين والمحافظة على علاقة مهنية ومستمرّة معهم.
A17: التخطيط المالي طويل المدى | B17: التخطيط المالي، جمع التمويل، الاستدامة | D17: مقترح المشروع | E17: وثيقة تشرح المشكلة والهدف والأنشطة والميزانية والنتائج المتوقعة للمشروع.
A18: تطوير قدرات الفريق في جمع التمويل | B18: بناء القدرات، جمع التمويل، كتابة المشاريع | D18: التخطيط المالي طويل المدى | E18: تقدير احتياجات المؤسسة ومصادر دخلها ونفقاتها لفترة مستقبلية طويلة.
D19: بناء القدرات | E19: تطوير مهارات الفريق ومعارفه حتى يؤدي عمله بشكل أفضل.

Sheet البنية التحتية والمعدات والتكنو
A5: البنية التحتية والمعدات والتكنولوجيا | B5: المؤشر / السؤال المبسط | C5: 1 - ناشئ | D5: 2 - أولي | E5: 3 - أساسي | F5: 4 - منظم | G5: 5 - ديناميكي | H5: الدرجة | I5: العلامة من 100
A6: إدارة البنية التحتية | B6: إلى أي مدى تدير مؤسستك المباني والمرافق والأصول المادية بصورة منظمة؟ | C6: لا تطبق مؤسستنا ممارسات واضحة في مجال إدارة البنية التحتية، وتتعامل معه عند الحاجة فقط. | D6: بدأت مؤسستنا باتخاذ خطوات بسيطة في مجال إدارة البنية التحتية، لكنها ما تزال محدودة وغير منتظمة. | E6: تطبق مؤسستنا ممارسات أساسية وواضحة في مجال إدارة البنية التحتية، لكنها لا تنفذها أو توثقها بشكل منتظم بالكامل. | F6: تطبق مؤسستنا إجراءات واضحة وموثقة في مجال إدارة البنية التحتية، وتنفذها بانتظام وتتابع نتائجها. | G6: تراجع مؤسستنا ممارسات إدارة البنية التحتية باستمرار، وتحلل النتائج والتغذية الراجعة وتستخدمها للتطوير واتخاذ القرارات. | H6: 1
A7: إدارة المعدات والتكنولوجيا | B7: إلى أي مدى تدير مؤسستك المعدات والأجهزة والتكنولوجيا وتتابع صيانتها واستخدامها؟ | C7: لا تطبق مؤسستنا ممارسات واضحة في مجال إدارة المعدات والتكنولوجيا، وتتعامل معه عند الحاجة فقط. | D7: بدأت مؤسستنا باتخاذ خطوات بسيطة في مجال إدارة المعدات والتكنولوجيا، لكنها ما تزال محدودة وغير منتظمة. | E7: تطبق مؤسستنا ممارسات أساسية وواضحة في مجال إدارة المعدات والتكنولوجيا، لكنها لا تنفذها أو توثقها بشكل منتظم بالكامل. | F7: تطبق مؤسستنا إجراءات واضحة وموثقة في مجال إدارة المعدات والتكنولوجيا، وتنفذها بانتظام وتتابع نتائجها. | G7: تراجع مؤسستنا ممارسات إدارة المعدات والتكنولوجيا باستمرار، وتحلل النتائج والتغذية الراجعة وتستخدمها للتطوير واتخاذ القرارات. | H7: 1
A8: السلامة في المرافق | B8: إلى أي مدى تضمن مؤسستك سلامة العاملين والمتعلمين والزوار داخل مرافقها؟ | C8: لا تطبق مؤسستنا ممارسات واضحة في مجال السلامة في المرافق، وتتعامل معه عند الحاجة فقط. | D8: بدأت مؤسستنا باتخاذ خطوات بسيطة في مجال السلامة في المرافق، لكنها ما تزال محدودة وغير منتظمة. | E8: تطبق مؤسستنا ممارسات أساسية وواضحة في مجال السلامة في المرافق، لكنها لا تنفذها أو توثقها بشكل منتظم بالكامل. | F8: تطبق مؤسستنا إجراءات واضحة وموثقة في مجال السلامة في المرافق، وتنفذها بانتظام وتتابع نتائجها. | G8: تراجع مؤسستنا ممارسات السلامة في المرافق باستمرار، وتحلل النتائج والتغذية الراجعة وتستخدمها للتطوير واتخاذ القرارات. | H8: 1
A9: الالتزام بالقوانين والأنظمة | B9: إلى أي مدى تلتزم مؤسستك بالقوانين والأنظمة المحلية المتعلقة بالمرافق والمعدات وأنظمة تكنولوجيا المعلومات؟ | C9: لا تطبق مؤسستنا ممارسات واضحة في مجال الالتزام بالقوانين والأنظمة، وتتعامل معه عند الحاجة فقط. | D9: بدأت مؤسستنا باتخاذ خطوات بسيطة في مجال الالتزام بالقوانين والأنظمة، لكنها ما تزال محدودة وغير منتظمة. | E9: تطبق مؤسستنا ممارسات أساسية وواضحة في مجال الالتزام بالقوانين والأنظمة، لكنها لا تنفذها أو توثقها بشكل منتظم بالكامل. | F9: تطبق مؤسستنا إجراءات واضحة وموثقة في مجال الالتزام بالقوانين والأنظمة، وتنفذها بانتظام وتتابع نتائجها. | G9: تراجع مؤسستنا ممارسات الالتزام بالقوانين والأنظمة باستمرار، وتحلل النتائج والتغذية الراجعة وتستخدمها للتطوير واتخاذ القرارات. | H9: 1
A10: الراحة وسهولة الوصول | B10: إلى أي مدى توفر مؤسستك بيئة مريحة وآمنة وسهلة الوصول لمختلف الأشخاص، بمن فيهم الأشخاص ذوو الإعاقة؟ | C10: لا تطبق مؤسستنا ممارسات واضحة في مجال الراحة وسهولة الوصول، وتتعامل معه عند الحاجة فقط. | D10: بدأت مؤسستنا باتخاذ خطوات بسيطة في مجال الراحة وسهولة الوصول، لكنها ما تزال محدودة وغير منتظمة. | E10: تطبق مؤسستنا ممارسات أساسية وواضحة في مجال الراحة وسهولة الوصول، لكنها لا تنفذها أو توثقها بشكل منتظم بالكامل. | F10: تطبق مؤسستنا إجراءات واضحة وموثقة في مجال الراحة وسهولة الوصول، وتنفذها بانتظام وتتابع نتائجها. | G10: تراجع مؤسستنا ممارسات الراحة وسهولة الوصول باستمرار، وتحلل النتائج والتغذية الراجعة وتستخدمها للتطوير واتخاذ القرارات. | H10: 1
G11: متوسط المجال | H11: =(H6+H7+H8+H9+H10)/5 -> 1 | I11: =H11*20 -> 20
A13: مصطلحات مساعدة | B13: شرح مبسط | D13: المصطلح | E13: التعريف
A14: إدارة البنية التحتية | B14: البنية التحتية، الأصول، الصيانة | D14: البنية التحتية | E14: المباني والغرف والمرافق والأنظمة الأساسية التي تحتاجها المؤسسة للعمل.
A15: إدارة المعدات والتكنولوجيا | B15: المعدات، التكنولوجيا، إدارة الأصول | D15: الأصول | E15: الممتلكات التي تملكها المؤسسة وتستخدمها، مثل الأجهزة والأثاث والمركبات.
A16: السلامة في المرافق | B16: السلامة، المخاطر، إجراءات الطوارئ | D16: الامتثال | E16: الالتزام بالقوانين والأنظمة والسياسات المطلوبة.
A17: الالتزام بالقوانين والأنظمة | B17: الامتثال، القوانين المحلية، تكنولوجيا المعلومات | D17: سهولة الوصول | E17: قدرة جميع الأشخاص على استخدام المكان أو الخدمة، بمن فيهم الأشخاص ذوو الإعاقة.
A18: الراحة وسهولة الوصول | B18: الراحة البيئية، سهولة الوصول، الترتيبات التيسيرية | D18: الترتيبات التيسيرية | E18: تجهيزات أو تعديلات تساعد الأشخاص على الوصول والمشاركة دون عوائق.

Sheet الإدارة المالية
A5: الإدارة المالية | B5: المؤشر / السؤال المبسط | C5: 1 - ناشئ | D5: 2 - أولي | E5: 3 - أساسي | F5: 4 - منظم | G5: 5 - ديناميكي | H5: الدرجة | I5: العلامة من 100
A6: النظام المحاسبي | B6: إلى أي مدى تستخدم مؤسستك نظامًا واضحًا ومنظمًا لتسجيل العمليات المالية وإدارتها؟ | C6: لا تطبق مؤسستنا ممارسات واضحة في مجال النظام المحاسبي، وتتعامل معه عند الحاجة فقط. | D6: بدأت مؤسستنا باتخاذ خطوات بسيطة في مجال النظام المحاسبي، لكنها ما تزال محدودة وغير منتظمة. | E6: تطبق مؤسستنا ممارسات أساسية وواضحة في مجال النظام المحاسبي، لكنها لا تنفذها أو توثقها بشكل منتظم بالكامل. | F6: تطبق مؤسستنا إجراءات واضحة وموثقة في مجال النظام المحاسبي، وتنفذها بانتظام وتتابع نتائجها. | G6: تراجع مؤسستنا ممارسات النظام المحاسبي باستمرار، وتحلل النتائج والتغذية الراجعة وتستخدمها للتطوير واتخاذ القرارات. | H6: 1
A7: الرقابة المالية والامتثال | B7: إلى أي مدى تطبق مؤسستك ضوابط مالية وتلتزم بالسياسات والمتطلبات المالية؟ | C7: لا تطبق مؤسستنا ممارسات واضحة في مجال الرقابة المالية والامتثال، وتتعامل معه عند الحاجة فقط. | D7: بدأت مؤسستنا باتخاذ خطوات بسيطة في مجال الرقابة المالية والامتثال، لكنها ما تزال محدودة وغير منتظمة. | E7: تطبق مؤسستنا ممارسات أساسية وواضحة في مجال الرقابة المالية والامتثال، لكنها لا تنفذها أو توثقها بشكل منتظم بالكامل. | F7: تطبق مؤسستنا إجراءات واضحة وموثقة في مجال الرقابة المالية والامتثال، وتنفذها بانتظام وتتابع نتائجها. | G7: تراجع مؤسستنا ممارسات الرقابة المالية والامتثال باستمرار، وتحلل النتائج والتغذية الراجعة وتستخدمها للتطوير واتخاذ القرارات. | H7: 1
A8: التخطيط المالي وإعداد الموازنة | B8: إلى أي مدى تخطط مؤسستك ماليًا وتعد الموازنات وتتابع تنفيذها؟ | C8: لا تطبق مؤسستنا ممارسات واضحة في مجال التخطيط المالي وإعداد الموازنة، وتتعامل معه عند الحاجة فقط. | D8: بدأت مؤسستنا باتخاذ خطوات بسيطة في مجال التخطيط المالي وإعداد الموازنة، لكنها ما تزال محدودة وغير منتظمة. | E8: تطبق مؤسستنا ممارسات أساسية وواضحة في مجال التخطيط المالي وإعداد الموازنة، لكنها لا تنفذها أو توثقها بشكل منتظم بالكامل. | F8: تطبق مؤسستنا إجراءات واضحة وموثقة في مجال التخطيط المالي وإعداد الموازنة، وتنفذها بانتظام وتتابع نتائجها. | G8: تراجع مؤسستنا ممارسات التخطيط المالي وإعداد الموازنة باستمرار، وتحلل النتائج والتغذية الراجعة وتستخدمها للتطوير واتخاذ القرارات. | H8: 1
A9: التحليل المالي واتخاذ القرار | B9: إلى أي مدى تحلل مؤسستك البيانات المالية وتستخدمها في اتخاذ القرارات؟ | C9: لا تطبق مؤسستنا ممارسات واضحة في مجال التحليل المالي واتخاذ القرار، وتتعامل معه عند الحاجة فقط. | D9: بدأت مؤسستنا باتخاذ خطوات بسيطة في مجال التحليل المالي واتخاذ القرار، لكنها ما تزال محدودة وغير منتظمة. | E9: تطبق مؤسستنا ممارسات أساسية وواضحة في مجال التحليل المالي واتخاذ القرار، لكنها لا تنفذها أو توثقها بشكل منتظم بالكامل. | F9: تطبق مؤسستنا إجراءات واضحة وموثقة في مجال التحليل المالي واتخاذ القرار، وتنفذها بانتظام وتتابع نتائجها. | G9: تراجع مؤسستنا ممارسات التحليل المالي واتخاذ القرار باستمرار، وتحلل النتائج والتغذية الراجعة وتستخدمها للتطوير واتخاذ القرارات. | H9: 1
A10: توزيع الموارد | B10: إلى أي مدى توزع مؤسستك مواردها وفق الأولويات والاحتياجات والأهداف؟ | C10: لا تطبق مؤسستنا ممارسات واضحة في مجال توزيع الموارد، وتتعامل معه عند الحاجة فقط. | D10: بدأت مؤسستنا باتخاذ خطوات بسيطة في مجال توزيع الموارد، لكنها ما تزال محدودة وغير منتظمة. | E10: تطبق مؤسستنا ممارسات أساسية وواضحة في مجال توزيع الموارد، لكنها لا تنفذها أو توثقها بشكل منتظم بالكامل. | F10: تطبق مؤسستنا إجراءات واضحة وموثقة في مجال توزيع الموارد، وتنفذها بانتظام وتتابع نتائجها. | G10: تراجع مؤسستنا ممارسات توزيع الموارد باستمرار، وتحلل النتائج والتغذية الراجعة وتستخدمها للتطوير واتخاذ القرارات. | H10: 1
A11: إدارة المخاطر المالية | B11: إلى أي مدى تحدد مؤسستك المخاطر المالية وتقيّمها وتتخذ إجراءات للتعامل معها؟ | C11: لا تطبق مؤسستنا ممارسات واضحة في مجال إدارة المخاطر المالية، وتتعامل معه عند الحاجة فقط. | D11: بدأت مؤسستنا باتخاذ خطوات بسيطة في مجال إدارة المخاطر المالية، لكنها ما تزال محدودة وغير منتظمة. | E11: تطبق مؤسستنا ممارسات أساسية وواضحة في مجال إدارة المخاطر المالية، لكنها لا تنفذها أو توثقها بشكل منتظم بالكامل. | F11: تطبق مؤسستنا إجراءات واضحة وموثقة في مجال إدارة المخاطر المالية، وتنفذها بانتظام وتتابع نتائجها. | G11: تراجع مؤسستنا ممارسات إدارة المخاطر المالية باستمرار، وتحلل النتائج والتغذية الراجعة وتستخدمها للتطوير واتخاذ القرارات. | H11: 1
A12: التقارير المالية | B12: إلى أي مدى تعد مؤسستك تقارير مالية دقيقة ومنتظمة وتستخدمها في المتابعة والمساءلة؟ | C12: لا تطبق مؤسستنا ممارسات واضحة في مجال التقارير المالية، وتتعامل معه عند الحاجة فقط. | D12: بدأت مؤسستنا باتخاذ خطوات بسيطة في مجال التقارير المالية، لكنها ما تزال محدودة وغير منتظمة. | E12: تطبق مؤسستنا ممارسات أساسية وواضحة في مجال التقارير المالية، لكنها لا تنفذها أو توثقها بشكل منتظم بالكامل. | F12: تطبق مؤسستنا إجراءات واضحة وموثقة في مجال التقارير المالية، وتنفذها بانتظام وتتابع نتائجها. | G12: تراجع مؤسستنا ممارسات التقارير المالية باستمرار، وتحلل النتائج والتغذية الراجعة وتستخدمها للتطوير واتخاذ القرارات. | H12: 1
G13: متوسط المجال | H13: =(H6+H7+H8+H9+H10+H11+H12)/7 -> 1 | I13: =H13*20 -> 20
D14: المصطلح | E14: التعريف
A15: مصطلحات مساعدة | B15: شرح مبسط | D15: النظام المحاسبي | E15: الطريقة أو النظام الذي تُسجّل به الإيرادات والمصروفات والعمليات المالية.
A16: النظام المحاسبي | B16: المحاسبة، السجلات المالية، العمليات المالية | D16: السجلات المالية | E16: الوثائق التي تثبت حركة الأموال، مثل الفواتير والإيصالات وكشوف الحسابات.
A17: الرقابة المالية والامتثال | B17: الرقابة المالية، الامتثال، السياسات | D17: الامتثال المالي | E17: الالتزام بالسياسات والقوانين والمتطلبات المتعلقة بإدارة الأموال.
A18: التخطيط المالي وإعداد الموازنة | B18: التخطيط المالي، الموازنة، التنبؤ المالي | D18: الموازنة | E18: خطة تقدّر الإيرادات والمصروفات المتوقعة خلال فترة معينة.
A19: التحليل المالي واتخاذ القرار | B19: التحليل المالي، التقارير المالية، اتخاذ القرار | D19: توزيع الموارد | E19: تخصيص المال والوقت والأفراد والمعدات حسب الأولويات والاحتياجات.
A20: توزيع الموارد | B20: تخصيص الموارد، الأولويات، الكفاءة | D20: المخاطر المالية | E20: أحداث قد تسبب خسارة مالية أو نقصًا في الموارد أو صعوبة في الاستمرار.
A21: إدارة المخاطر المالية | B21: إدارة المخاطر، تقييم المخاطر، إجراءات التخفيف | D21: المساءلة | E21: توضيح كيفية استخدام الأموال وتحمل المسؤولية عن القرارات والنتائج.
A22: التقارير المالية | B22: التقارير المالية، الدقة، المساءلة

Sheet الإدارة والحوكمة
A5: الإدارة والحوكمة | B5: المؤشر / السؤال المبسط | C5: 1 - ناشئ | D5: 2 - أولي | E5: 3 - أساسي | F5: 4 - منظم | G5: 5 - ديناميكي | H5: الدرجة | I5: العلامة من 100
A6: اتخاذ القرار بكفاءة | B6: إلى أي مدى تطبق مؤسستك إجراءات واضحة لاتخاذ القرارات بسرعة وكفاءة وبمشاركة العاملين والمدربين المعنيين؟ | C6: لا تطبق مؤسستنا ممارسات واضحة في مجال اتخاذ القرار بكفاءة، وتتعامل معه عند الحاجة فقط. | D6: بدأت مؤسستنا باتخاذ خطوات بسيطة في مجال اتخاذ القرار بكفاءة، لكنها ما تزال محدودة وغير منتظمة. | E6: تطبق مؤسستنا ممارسات أساسية وواضحة في مجال اتخاذ القرار بكفاءة، لكنها لا تنفذها أو توثقها بشكل منتظم بالكامل. | F6: تطبق مؤسستنا إجراءات واضحة وموثقة في مجال اتخاذ القرار بكفاءة، وتنفذها بانتظام وتتابع نتائجها. | G6: تراجع مؤسستنا ممارسات اتخاذ القرار بكفاءة باستمرار، وتحلل النتائج والتغذية الراجعة وتستخدمها للتطوير واتخاذ القرارات. | H6: 1
A7: مواءمة القرارات مع الأهداف الاستراتيجية | B7: إلى أي مدى تربط مؤسستك القرارات الإدارية وتوزيع الموارد بأهدافها الاستراتيجية؟ | C7: لا تطبق مؤسستنا ممارسات واضحة في مجال مواءمة القرارات مع الأهداف الاستراتيجية، وتتعامل معه عند الحاجة فقط. | D7: بدأت مؤسستنا باتخاذ خطوات بسيطة في مجال مواءمة القرارات مع الأهداف الاستراتيجية، لكنها ما تزال محدودة وغير منتظمة. | E7: تطبق مؤسستنا ممارسات أساسية وواضحة في مجال مواءمة القرارات مع الأهداف الاستراتيجية، لكنها لا تنفذها أو توثقها بشكل منتظم بالكامل. | F7: تطبق مؤسستنا إجراءات واضحة وموثقة في مجال مواءمة القرارات مع الأهداف الاستراتيجية، وتنفذها بانتظام وتتابع نتائجها. | G7: تراجع مؤسستنا ممارسات مواءمة القرارات مع الأهداف الاستراتيجية باستمرار، وتحلل النتائج والتغذية الراجعة وتستخدمها للتطوير واتخاذ القرارات. | H7: 1
A8: مراجعة الممارسات الإدارية | B8: إلى أي مدى تراجع مؤسستك ممارساتها الإدارية وتعدلها للاستجابة للتغيرات؟ | C8: لا تطبق مؤسستنا ممارسات واضحة في مجال مراجعة الممارسات الإدارية، وتتعامل معه عند الحاجة فقط. | D8: بدأت مؤسستنا باتخاذ خطوات بسيطة في مجال مراجعة الممارسات الإدارية، لكنها ما تزال محدودة وغير منتظمة. | E8: تطبق مؤسستنا ممارسات أساسية وواضحة في مجال مراجعة الممارسات الإدارية، لكنها لا تنفذها أو توثقها بشكل منتظم بالكامل. | F8: تطبق مؤسستنا إجراءات واضحة وموثقة في مجال مراجعة الممارسات الإدارية، وتنفذها بانتظام وتتابع نتائجها. | G8: تراجع مؤسستنا ممارسات مراجعة الممارسات الإدارية باستمرار، وتحلل النتائج والتغذية الراجعة وتستخدمها للتطوير واتخاذ القرارات. | H8: 1
A9: تطوير مهارات المديرين في إدارة المشاريع | B9: إلى أي مدى توفر مؤسستك تدريبًا مستمرًا للمديرين على إدارة المشاريع وتتابع تطبيق ما تعلموه؟ | C9: لا تطبق مؤسستنا ممارسات واضحة في مجال تطوير مهارات المديرين في إدارة المشاريع، وتتعامل معه عند الحاجة فقط. | D9: بدأت مؤسستنا باتخاذ خطوات بسيطة في مجال تطوير مهارات المديرين في إدارة المشاريع، لكنها ما تزال محدودة وغير منتظمة. | E9: تطبق مؤسستنا ممارسات أساسية وواضحة في مجال تطوير مهارات المديرين في إدارة المشاريع، لكنها لا تنفذها أو توثقها بشكل منتظم بالكامل. | F9: تطبق مؤسستنا إجراءات واضحة وموثقة في مجال تطوير مهارات المديرين في إدارة المشاريع، وتنفذها بانتظام وتتابع نتائجها. | G9: تراجع مؤسستنا ممارسات تطوير مهارات المديرين في إدارة المشاريع باستمرار، وتحلل النتائج والتغذية الراجعة وتستخدمها للتطوير واتخاذ القرارات. | H9: 1
A10: التخطيط الاستراتيجي | B10: إلى أي مدى تحدد مؤسستك رؤيتها ورسالتها وأهدافها طويلة المدى وتحولها إلى خطط قابلة للتنفيذ؟ | C10: لا تطبق مؤسستنا ممارسات واضحة في مجال التخطيط الاستراتيجي، وتتعامل معه عند الحاجة فقط. | D10: بدأت مؤسستنا باتخاذ خطوات بسيطة في مجال التخطيط الاستراتيجي، لكنها ما تزال محدودة وغير منتظمة. | E10: تطبق مؤسستنا ممارسات أساسية وواضحة في مجال التخطيط الاستراتيجي، لكنها لا تنفذها أو توثقها بشكل منتظم بالكامل. | F10: تطبق مؤسستنا إجراءات واضحة وموثقة في مجال التخطيط الاستراتيجي، وتنفذها بانتظام وتتابع نتائجها. | G10: تراجع مؤسستنا ممارسات التخطيط الاستراتيجي باستمرار، وتحلل النتائج والتغذية الراجعة وتستخدمها للتطوير واتخاذ القرارات. | H10: 1
A11: إدارة المشاريع | B11: إلى أي مدى تخطط مؤسستك للمشاريع وتنفذها وتغلقها ضمن النطاق والوقت والموازنة المحددة؟ | C11: لا تطبق مؤسستنا ممارسات واضحة في مجال إدارة المشاريع، وتتعامل معه عند الحاجة فقط. | D11: بدأت مؤسستنا باتخاذ خطوات بسيطة في مجال إدارة المشاريع، لكنها ما تزال محدودة وغير منتظمة. | E11: تطبق مؤسستنا ممارسات أساسية وواضحة في مجال إدارة المشاريع، لكنها لا تنفذها أو توثقها بشكل منتظم بالكامل. | F11: تطبق مؤسستنا إجراءات واضحة وموثقة في مجال إدارة المشاريع، وتنفذها بانتظام وتتابع نتائجها. | G11: تراجع مؤسستنا ممارسات إدارة المشاريع باستمرار، وتحلل النتائج والتغذية الراجعة وتستخدمها للتطوير واتخاذ القرارات. | H11: 1
A12: تشجيع الابتكار | B12: إلى أي مدى تشجع مؤسستك الأفكار الجديدة والإبداع وتستخدمها لتحسين عملها؟ | C12: لا تطبق مؤسستنا ممارسات واضحة في مجال تشجيع الابتكار، وتتعامل معه عند الحاجة فقط. | D12: بدأت مؤسستنا باتخاذ خطوات بسيطة في مجال تشجيع الابتكار، لكنها ما تزال محدودة وغير منتظمة. | E12: تطبق مؤسستنا ممارسات أساسية وواضحة في مجال تشجيع الابتكار، لكنها لا تنفذها أو توثقها بشكل منتظم بالكامل. | F12: تطبق مؤسستنا إجراءات واضحة وموثقة في مجال تشجيع الابتكار، وتنفذها بانتظام وتتابع نتائجها. | G12: تراجع مؤسستنا ممارسات تشجيع الابتكار باستمرار، وتحلل النتائج والتغذية الراجعة وتستخدمها للتطوير واتخاذ القرارات. | H12: 1
G13: متوسط المجال | H13: =(H6+H7+H8+H9+H10+H11+H12)/7 -> 1 | I13: =H13*20 -> 20
A15: مصطلحات مساعدة | B15: شرح مبسط | D15: المصطلح | E15: التعريف
A16: اتخاذ القرار بكفاءة | B16: اتخاذ القرار، الكفاءة، المشاركة | D16: الحوكمة | E16: القواعد والأدوار والإجراءات التي تنظّم إدارة المؤسسة واتخاذ القرارات فيها.
A17: مواءمة القرارات مع الأهداف الاستراتيجية | B17: الأهداف الاستراتيجية، تخصيص الموارد، المواءمة | D17: الأهداف الاستراتيجية | E17: النتائج الكبيرة التي تريد المؤسسة تحقيقها على المدى المتوسط أو الطويل.
A18: مراجعة الممارسات الإدارية | B18: المراجعة الإدارية، المرونة، الاستجابة للتغيير | D18: إدارة المشاريع | E18: تخطيط المشروع وتنفيذه ومتابعته وإنهاؤه ضمن الوقت والموارد المحددة.
A19: تطوير مهارات المديرين في إدارة المشاريع | B19: إدارة المشاريع، تدريب المديرين، المتابعة والتقييم | D19: الموازنة الخاصة بالمشروع | E19: المبلغ المخطط لإنفاقه على أنشطة المشروع المختلفة.
A20: التخطيط الاستراتيجي | B20: الرؤية، الرسالة، الأهداف الاستراتيجية، SMART | D20: التخطيط الاستراتيجي | E20: تحديد رؤية المؤسسة ورسالتها وأهدافها ووضع خطط عملية لتحقيقها.
A21: إدارة المشاريع | B21: إدارة المشاريع، النطاق، الوقت، الموازنة | D21: الرؤية | E21: الصورة أو الوضع الذي تطمح المؤسسة إلى الوصول إليه مستقبلًا.
A22: تشجيع الابتكار | B22: الابتكار، الإبداع، التحسين | D22: الرسالة | E22: سبب وجود المؤسسة وما تقدمه ولمن تقدمه.
D23: SMART | E23: طريقة لصياغة الأهداف بحيث تكون محددة، وقابلة للقياس، وقابلة للتحقيق، ومرتبطة بالهدف، ومحددة بزمن.

Sheet سجل المرفقات الداعمة
A5: سجل المرفقات الداعمة والتحقق لمحاور KPI
A6: المرفقات الداعمة محتملة واختيارية. لا يشترط تقديم مرفق لكل سؤال، ويمكن لمرفق واحد أن يدعم أكثر من سؤال. يرجى إخفاء البيانات الشخصية والمالية الحساسة.
A8: المحور | B8: رقم السؤال | C8: المؤشر | D8: المرفقات الداعمة المحتملة | E8: اسم المرفق المرسل | F8: حالة التحقق | G8: ملاحظات
A9: الترويج والخبرة في تعلم وتعليم الكبار | B9: 1 | C9: تحسين الصورة العامة لتعلم وتعليم الكبار | D9: خطة تواصل أو توعية، منشورات أو مواد إعلامية، رابط موقع أو صفحة إلكترونية، أو تقرير نتائج حملة.
A10: الترويج والخبرة في تعلم وتعليم الكبار | B10: 2 | C10: المشاركة في المعرفة والنقاشات | D10: دعوة أو شهادة حضور، عرض تقديمي، ورقة أو منشور، محضر اجتماع، أو رابط مشاركة المؤسسة.
A11: الترويج والخبرة في تعلم وتعليم الكبار | B11: 3 | C11: المناصرة لتعلم وتعليم الكبار | D11: خطة أو سياسة مناصرة، رسائل للجهات المعنية، محاضر لقاءات، مواد توعية، أو أمثلة على حشد الدعم.
A12: الترويج والخبرة في تعلم وتعليم الكبار | B12: 4 | C12: استخدام منهجيات تعلم الكبار | D12: دليل تدريبي، خطة جلسة، مادة تدريبية، نموذج يوضح أساليب تعليم الكبار، أو تقرير تدريب للمدربين.
A13: الترويج والخبرة في تعلم وتعليم الكبار | B13: 5 | C13: التشبيك والتعاون | D13: اتفاقية أو مذكرة تفاهم، قائمة شركاء، محضر اجتماع مشترك، خطة تعاون، أو تقرير نشاط مشترك.
A14: الترويج والخبرة في تعلم وتعليم الكبار | B14: 6 | C14: تدريب الفريق على أساليب تعلم الكبار | D14: خطة تدريب، سجل حضور، شهادات، مواد تدريب، تقييم بعد التدريب، أو خطة متابعة التطبيق.
A15: برامج تعلم وتعليم الكبار | B15: 1 | C15: تنوع وتنظيم البرامج التعليمية | D15: قائمة البرامج، وصف البرامج، خطة سنوية، جدول الدورات، أو تقرير ارتباط البرامج باحتياجات المتعلمين.
A16: برامج تعلم وتعليم الكبار | B16: 2 | C16: جودة المناهج وتقييمها | D16: نسخة من المنهج أو الدليل التدريبي، نموذج مراجعة المحتوى، محضر مراجعة، أو سجل تحديث المناهج.
A17: برامج تعلم وتعليم الكبار | B17: 3 | C17: تنوع أشكال تقديم الدورات | D17: جدول الدورات الوجاهية والرقمية والمدمجة، رابط المنصة، لقطات من البيئة الرقمية، أو دليل استخدام المنصة.
A18: برامج تعلم وتعليم الكبار | B18: 4 | C18: إتاحة البرامج للمشاركين | D18: سياسة أو إجراءات التسجيل، إعلان البرنامج، ترتيبات تيسيرية، خطة إزالة العوائق، أو دليل سهولة الوصول.
A19: برامج تعلم وتعليم الكبار | B19: 5 | C19: تغذية المشاركين الراجعة ورضاهم | D19: نموذج تقييم، استبيان رضا، ملخص النتائج، تقرير ملاحظات، أو مثال على تعديل بناءً على آراء المشاركين.
A20: برامج تعلم وتعليم الكبار | B20: 6 | C20: التوجيه والإرشاد المهني | D20: نموذج جلسة إرشاد، خطة خدمة، سجل إحالات، دليل الخدمات، أو تقرير عام عن المستفيدين.
... A66: الإدارة والحوكمة | B66: 7 | C66: تشجيع الابتكار | D66: سياسة أو صندوق أفكار، سجل مقترحات، محضر تقييم الأفكار، تجربة تجريبية، أو أمثلة تحسينات منفذة.

Sheet النتائج
A5: اسم المحور | B5: عدد المؤشرات | C5: متوسط الدرجة | D5: المستوى | E5: العلامة من 100
A6: الترويج والخبرة في تعلم الكبار | B6: 6 | C6: ='الترويج والخبرة في تعلم الكبار'!H11 -> 1 | D6: =IF(C6="","",IF(C6<1.5,"ناشئ",IF(C6<2.5,"أولي",IF(C6<3.5,"أساسي",IF(C6<4.5,"منظم","ديناميكي"))))) -> ناشئ | E6: ='الترويج والخبرة في تعلم الكبار'!I11 -> 20
A7: برامج تعلم وتعليم الكبار | B7: 9 | C7: ='برامج تعلم وتعليم الكبار'!H15 -> 1 | D7: =IF(C7="","",IF(C7<1.5,"ناشئ",IF(C7<2.5,"أولي",IF(C7<3.5,"أساسي",IF(C7<4.5,"منظم","ديناميكي"))))) -> ناشئ | E7: ='برامج تعلم وتعليم الكبار'!I15 -> 20
A8: البحث المجتمعي والتواصل | B8: 7 | C8: ='البحث المجتمعي والتواصل'!H13 -> 1 | D8: =IF(C8="","",IF(C8<1.5,"ناشئ",IF(C8<2.5,"أولي",IF(C8<3.5,"أساسي",IF(C8<4.5,"منظم","ديناميكي"))))) -> ناشئ | E8: ='البحث المجتمعي والتواصل'!I13 -> 20
A9: التواصل والمناصرة | B9: 6 | C9: ='التواصل والمناصرة'!H12 -> 1 | D9: =IF(C9="","",IF(C9<1.5,"ناشئ",IF(C9<2.5,"أولي",IF(C9<3.5,"أساسي",IF(C9<4.5,"منظم","ديناميكي"))))) -> ناشئ | E9: ='التواصل والمناصرة'!I12 -> 20
A10: الموارد البشرية | B10: 6 | C10: ='الموارد البشرية'!H12 -> 1 | D10: =IF(C10="","",IF(C10<1.5,"ناشئ",IF(C10<2.5,"أولي",IF(C10<3.5,"أساسي",IF(C10<4.5,"منظم","ديناميكي"))))) -> ناشئ | E10: ='الموارد البشرية'!I12 -> 20
A11: جمع التمويل وكتابة المشاريع | B11: 5 | C11: =' التمويل وكتابة المشاريع'!H11 -> 1 | D11: =IF(C11="","",IF(C11<1.5,"ناشئ",IF(C11<2.5,"أولي",IF(C11<3.5,"أساسي",IF(C11<4.5,"منظم","ديناميكي"))))) -> ناشئ | E11: =' التمويل وكتابة المشاريع'!I11 -> 20
A12: البنية التحتية والمعدات والتكنو | B12: 5 | C12: ='البنية التحتية والمعدات والتكنو'!H11 -> 1 | D12: =IF(C12="","",IF(C12<1.5,"ناشئ",IF(C12<2.5,"أولي",IF(C12<3.5,"أساسي",IF(C12<4.5,"منظم","ديناميكي"))))) -> ناشئ | E12: ='البنية التحتية والمعدات والتكنو'!I11 -> 20
A13: الإدارة المالية | B13: 7 | C13: ='الإدارة المالية'!H13 -> 1 | D13: =IF(C13="","",IF(C13<1.5,"ناشئ",IF(C13<2.5,"أولي",IF(C13<3.5,"أساسي",IF(C13<4.5,"منظم","ديناميكي"))))) -> ناشئ | E13: ='الإدارة المالية'!I13 -> 20
A14: الإدارة والحوكمة | B14: 7 | C14: ='الإدارة والحوكمة'!H13 -> 1 | D14: =IF(C14="","",IF(C14<1.5,"ناشئ",IF(C14<2.5,"أولي",IF(C14<3.5,"أساسي",IF(C14<4.5,"منظم","ديناميكي"))))) -> ناشئ | E14: ='الإدارة والحوكمة'!I13 -> 20
A15: المتوسط العام | D15: =IF(ISNUMBER(E15),CHOOSE(MIN(5,MAX(1,ROUND(E15/20,0))),"ناشئ","أولي","أساسي","منظم","ديناميكي"),"قيد الاستكمال") -> ناشئ | E15: =IF(COUNTIF(E6:E14,">0")<9,"قيد الاستكمال",AVERAGEIF(E6:E14,">0")) -> 20

Sheet كشف التحصيل
A5: النتائج
B6: المستوى | C6: ناشئ -1 | D6: أولي-2 | E6: أساسي-3 | F6: منظم-4 | G6: ديناميكي-5 | H6: العلامة من 100 | J6: المستوى
B7: الوزن | C7: 1 | D7: 2 | E7: 3 | F7: 4 | G7: 5
A8: الترويج والخبرة في تعلم الكبار | B8: مجموع النقاط | C8: =IF('الترويج والخبرة في تعلم الكبار'!H5=1,1,0)+IF('الترويج والخبرة في تعلم الكبار'!H6=1,1,0)+IF('الترويج والخبرة في تعلم الكبار'!H7=1,1,0)+IF('الترويج والخبرة في تعلم الكبار'!H8=1,1,0)+IF('الترويج والخبرة في تعلم الكبار'!H9=1,1,0)+IF('الترويج والخبرة في تعلم الكبار'!H10=1,1,0) -> 6 | D8: =IF('الترويج والخبرة في تعلم الكبار'!H5=2,1,0)+IF('الترويج والخبرة في تعلم الكبار'!H6=2,1,0)+IF('الترويج والخبرة في تعلم الكبار'!H7=2,1,0)+IF('الترويج والخبرة في تعلم الكبار'!H8=2,1,0)+IF('الترويج والخبرة في تعلم الكبار'!H9=2,1,0)+IF('الترويج والخبرة في تعلم الكبار'!H10=2,1,0) -> 0 | E8: =IF('الترويج والخبرة في تعلم الكبار'!H5=3,1,0)+IF('الترويج والخبرة في تعلم الكبار'!H6=3,1,0)+IF('الترويج والخبرة في تعلم الكبار'!H7=3,1,0)+IF('الترويج والخبرة في تعلم الكبار'!H8=3,1,0)+IF('الترويج والخبرة في تعلم الكبار'!H9=3,1,0)+IF('الترويج والخبرة في تعلم الكبار'!H10=3,1,0) -> 0 | F8: =IF('الترويج والخبرة في تعلم الكبار'!H5=4,1,0)+IF('الترويج والخبرة في تعلم الكبار'!H6=4,1,0)+IF('الترويج والخبرة في تعلم الكبار'!H7=4,1,0)+IF('الترويج والخبرة في تعلم الكبار'!H8=4,1,0)+IF('الترويج والخبرة في تعلم الكبار'!H9=4,1,0)+IF('الترويج والخبرة في تعلم الكبار'!H10=4,1,0) -> 0 | G8: =IF('الترويج والخبرة في تعلم الكبار'!H5=5,1,0)+IF('الترويج والخبرة في تعلم الكبار'!H6=5,1,0)+IF('الترويج والخبرة في تعلم الكبار'!H7=5,1,0)+IF('الترويج والخبرة في تعلم الكبار'!H8=5,1,0)+IF('الترويج والخبرة في تعلم الكبار'!H9=5,1,0)+IF('الترويج والخبرة في تعلم الكبار'!H10=5,1,0) -> 0
B9: التحصيل | C9: =C8*1 -> 6 | D9: =D8*2 -> 0 | E9: =E8*3 -> 0 | F9: =F8*4 -> 0 | G9: =G8*5 -> 0 | H9: =IF(SUM(C8:G8)=0,"قيد الاستكمال",((C9+D9+E9+F9+G9)/((C8+D8+E8+F8+G8)*5))*100) -> 20
